Workbook
Name Slicer_age_group: #N/A
Name Slicer_BMI_Category: #N/A
Name Slicer_gender: #N/A
Name Slicer_High_Cholesterol_Flag: #N/A
Name Slicer_smoker_Category: #N/A
Name Slicer_TenYearCHD: #N/A

Sheet framingham
A1: male | B1: gender | C1: age | D1: age_group | E1: education_clean | F1: Lookup | G1: Education_Level | H1: currentSmoker | I1: cigsPerDay_Clean | J1: smoker_Category | K1: BPMeds_Clean | L1: prevalentStroke | M1: prevalentHyp | N1: diabetes | O1: totChol_Clean | P1: High_Cholesterol_Flag | Q1: sysBP | R1: diaBP | S1: BMI_Clean | T1: BMI_Category | U1: heartRate_Clean | V1: glucose_Clean | W1: glucose_category | X1: TenYearCHD
A2: 0 | B2: =IF(A2=0,"Female","Male") -> Female | C2: 32 | D2: =IF(C2<40,"Young", IF(C2<55,"Middle Age","Senior")) -> Young | E2: 2 | F2: =HLOOKUP(E2, LookUP_Table!$A$6:$D$7, 2, FALSE) -> Secondary | G2: =IFERROR(VLOOKUP(E2, LookUP_Table!$A$1:$B$4, 2, FALSE), "") -> Secondary | H2: 1 | I2: 15 | J2: =IF(I2>0,"Smoker","Non-Smoker") -> Smoker | K2: 0 | L2: 0 | M2: 0 | N2: 0 | O2: 242 | P2: =IF(O2>240,"High","Normal") -> High | Q2: 111 | R2: 70 | S2: 29.84 | T2: =IF(S2<18.5,"Underweight", IF(S2<25,"Normal", IF(S2<30,"Overweight","Obese"))) -> Overweight | U2: 80 | V2: 88 | W2: =IF(V2 < 100, "Normal", IF(V2 <= 125, "Prediabetes", "Diabetes")) -> Normal | X2: 0
A3: 0 | B3: =IF(A3=0,"Female","Male") -> Female | C3: 33 | D3: =IF(C3<40,"Young", IF(C3<55,"Middle Age","Senior")) -> Young | E3: 3 | F3: =HLOOKUP(E3, LookUP_Table!$A$6:$D$7, 2, FALSE) -> Graduate | G3: =IFERROR(VLOOKUP(E3, LookUP_Table!$A$1:$B$4, 2, FALSE), "") -> Graduate | H3: 1 | I3: 15 | J3: =IF(I3>0,"Smoker","Non-Smoker") -> Smoker | K3: 0 | L3: 0 | M3: 0 | N3: 0 | O3: 199 | P3: =IF(O3>240,"High","Normal") -> Normal | Q3: 116 | R3: 81 | S3: 21.61 | T3: =IF(S3<18.5,"Underweight", IF(S3<25,"Normal", IF(S3<30,"Overweight","Obese"))) -> Normal | U3: 75 | V3: 93 | W3: =IF(V3 < 100, "Normal", IF(V3 <= 125, "Prediabetes", "Diabetes")) -> Normal | X3: 0
A4: 0 | B4: =IF(A4=0,"Female","Male") -> Female | C4: 33 | D4: =IF(C4<40,"Young", IF(C4<55,"Middle Age","Senior")) -> Young | E4: 1 | F4: =HLOOKUP(E4, LookUP_Table!$A$6:$D$7, 2, FALSE) -> Primary | G4: =IFERROR(VLOOKUP(E4, LookUP_Table!$A$1:$B$4, 2, FALSE), "") -> Primary | H4: 0 | I4: 0 | J4: =IF(I4>0,"Smoker","Non-Smoker") -> Non-Smoker | K4: 0 | L4: 0 | M4: 0 | N4: 0 | O4: 158 | P4: =IF(O4>240,"High","Normal") -> Normal | Q4: 108 | R4: 67 | S4: 19.84 | T4: =IF(S4<18.5,"Underweight", IF(S4<25,"Normal", IF(S4<30,"Overweight","Obese"))) -> Normal | U4: 86 | V4: 69 | W4: =IF(V4 < 100, "Normal", IF(V4 <= 125, "Prediabetes", "Diabetes")) -> Normal | X4: 0
A5: 1 | B5: =IF(A5=0,"Female","Male") -> Male | C5: 33 | D5: =IF(C5<40,"Young", IF(C5<55,"Middle Age","Senior")) -> Young | E5: 2 | F5: =HLOOKUP(E5, LookUP_Table!$A$6:$D$7, 2, FALSE) -> Secondary | G5: =IFERROR(VLOOKUP(E5, LookUP_Table!$A$1:$B$4, 2, FALSE), "") -> Secondary | H5: 0 | I5: 0 | J5: =IF(I5>0,"Smoker","Non-Smoker") -> Non-Smoker | K5: 0 | L5: 0 | M5: 1 | N5: 0 | O5: 165 | P5: =IF(O5>240,"High","Normal") -> Normal | Q5: 141.5 | R5: 95 | S5: 26.74 | T5: =IF(S5<18.5,"Underweight", IF(S5<25,"Normal", IF(S5<30,"Overweight","Obese"))) -> Overweight | U5: 54 | V5: 77 | W5: =IF(V5 < 100, "Normal", IF(V5 <= 125, "Prediabetes", "Diabetes")) -> Normal | X5: 0
A6: 0 | B6: =IF(A6=0,"Female","Male") -> Female | C6: 33 | D6: =IF(C6<40,"Young", IF(C6<55,"Middle Age","Senior")) -> Young | E6: 2 | F6: =HLOOKUP(E6, LookUP_Table!$A$6:$D$7, 2, FALSE) -> Secondary | G6: =IFERROR(VLOOKUP(E6, LookUP_Table!$A$1:$B$4, 2, FALSE), "") -> Secondary | H6: 1 | I6: 5 | J6: =IF(I6>0,"Smoker","Non-Smoker") -> Smoker | K6: 0 | L6: 0 | M6: 0 | N6: 0 | O6: 200 | P6: =IF(O6>240,"High","Normal") -> Normal | Q6: 119 | R6: 74 | S6: 23.8 | T6: =IF(S6<18.5,"Underweight", IF(S6<25,"Normal", IF(S6<30,"Overweight","Obese"))) -> Normal | U6: 75 | V6: 74 | W6: =IF(V6 < 100, "Normal", IF(V6 <= 125, "Prediabetes", "Diabetes")) -> Normal | X6: 0
A7: 1 | B7: =IF(A7=0,"Female","Male") -> Male | C7: 33 | D7: =IF(C7<40,"Young", IF(C7<55,"Middle Age","Senior")) -> Young | E7: 4 | F7: =HLOOKUP(E7, LookUP_Table!$A$6:$D$7, 2, FALSE) -> Post Graduate | G7: =IFERROR(VLOOKUP(E7, LookUP_Table!$A$1:$B$4, 2, FALSE), "") -> Post Graduate | H7: 0 | I7: 0 | J7: =IF(I7>0,"Smoker","Non-Smoker") -> Non-Smoker | K7: 0 | L7: 0 | M7: 0 | N7: 0 | O7: 165 | P7: =IF(O7>240,"High","Normal") -> Normal | Q7: 136 | R7: 75 | S7: 24.95 | T7: =IF(S7<18.5,"Underweight", IF(S7<25,"Normal", IF(S7<30,"Overweight","Obese"))) -> Normal | U7: 88 | V7: 90 | W7: =IF(V7 < 100, "Normal", IF(V7 <= 125, "Prediabetes", "Diabetes")) -> Normal | X7: 0
A8: 0 | B8: =IF(A8=0,"Female","Male") -> Female | C8: 34 | D8: =IF(C8<40,"Young", IF(C8<55,"Middle Age","Senior")) -> Young | E8: 1 | F8: =HLOOKUP(E8, LookUP_Table!$A$6:$D$7, 2, FALSE) -> Primary | G8: =IFERROR(VLOOKUP(E8, LookUP_Table!$A$1:$B$4, 2, FALSE), "") -> Primary | H8: 0 | I8: 0 | J8: =IF(I8>0,"Smoker","Non-Smoker") -> Non-Smoker | K8: 0 | L8: 0 | M8: 0 | N8: 0 | O8: 163 | P8: =IF(O8>240,"High","Normal") -> Normal | Q8: 107 | R8: 71 | S8: 23.88 | T8: =IF(S8<18.5,"Underweight", IF(S8<25,"Normal", IF(S8<30,"Overweight","Obese"))) -> Normal | U8: 73 | V8: 80 | W8: =IF(V8 < 100, "Normal", IF(V8 <= 125, "Prediabetes", "Diabetes")) -> Normal | X8: 0
A9: 0 | B9: =IF(A9=0,"Female","Male") -> Female | C9: 34 | D9: =IF(C9<40,"Young", IF(C9<55,"Middle Age","Senior")) -> Young | E9: 3 | F9: =HLOOKUP(E9, LookUP_Table!$A$6:$D$7, 2, FALSE) -> Graduate | G9: =IFERROR(VLOOKUP(E9, LookUP_Table!$A$1:$B$4, 2, FALSE), "") -> Graduate | H9: 1 | I9: 10 | J9: =IF(I9>0,"Smoker","Non-Smoker") -> Smoker | K9: 0 | L9: 0 | M9: 0 | N9: 0 | O9: 206 | P9: =IF(O9>240,"High","Normal") -> Normal | Q9: 101 | R9: 63 | S9: 21.5 | T9: =IF(S9<18.5,"Underweight", IF(S9<25,"Normal", IF(S9<30,"Overweight","Obese"))) -> Normal | U9: 75 | V9: 66 | W9: =IF(V9 < 100, "Normal", IF(V9 <= 125, "Prediabetes", "Diabetes")) -> Normal | X9: 0
A10: 0 | B10: =IF(A10=0,"Female","Male") -> Female | C10: 34 | D10: =IF(C10<40,"Young", IF(C10<55,"Middle Age","Senior")) -> Young | E10: 2 | F10: =HLOOKUP(E10, LookUP_Table!$A$6:$D$7, 2, FALSE) -> Secondary | G10: =IFERROR(VLOOKUP(E10, LookUP_Table!$A$1:$B$4, 2, FALSE), "") -> Secondary | H10: 0 | I10: 0 | J10: =IF(I10>0,"Smoker","Non-Smoker") -> Non-Smoker | K10: 0 | L10: 0 | M10: 0 | N10: 0 | O10: 189 | P10: =IF(O10>240,"High","Normal") -> Normal | Q10: 108 | R10: 66 | S10: 20.81 | T10: =IF(S10<18.5,"Underweight", IF(S10<25,"Normal", IF(S10<30,"Overweight","Obese"))) -> Normal | U10: 78 | V10: 88 | W10: =IF(V10 < 100, "Normal", IF(V10 <= 125, "Prediabetes", "Diabetes")) -> Normal | X10: 0
A11: 1 | B11: =IF(A11=0,"Female","Male") -> Male | C11: 34 | D11: =IF(C11<40,"Young", IF(C11<55,"Middle Age","Senior")) -> Young | E11: 2 | F11: =HLOOKUP(E11, LookUP_Table!$A$6:$D$7, 2, FALSE) -> Secondary | G11: =IFERROR(VLOOKUP(E11, LookUP_Table!$A$1:$B$4, 2, FALSE), "") -> Secondary | H11: 1 | I11: 25 | J11: =IF(I11>0,"Smoker","Non-Smoker") -> Smoker | K11: 0 | L11: 0 | M11: 0 | N11: 0 | O11: 250 | P11: =IF(O11>240,"High","Normal") -> High | Q11: 119 | R11: 77 | S11: 29.04 | T11: =IF(S11<18.5,"Underweight", IF(S11<25,"Normal", IF(S11<30,"Overweight","Obese"))) -> Overweight | U11: 63 | V11: 80 | W11: =IF(V11 < 100, "Normal", IF(V11 <= 125, "Prediabetes", "Diabetes")) -> Normal | X11: 0
A12: 1 | B12: =IF(A12=0,"Female","Male") -> Male | C12: 34 | D12: =IF(C12<40,"Young", IF(C12<55,"Middle Age","Senior")) -> Young | E12: 1 | F12: =HLOOKUP(E12, LookUP_Table!$A$6:$D$7, 2, FALSE) -> Primary | G12: =IFERROR(VLOOKUP(E12, LookUP_Table!$A$1:$B$4, 2, FALSE), "") -> Primary | H12: 1 | I12: 10 | J12: =IF(I12>0,"Smoker","Non-Smoker") -> Smoker | K12: 0 | L12: 0 | M12: 0 | N12: 0 | O12: 210 | P12: =IF(O12>240,"High","Normal") -> Normal | Q12: 120 | R12: 85 | S12: 24.39 | T12: =IF(S12<18.5,"Underweight", IF(S12<25,"Normal", IF(S12<30,"Overweight","Obese"))) -> Normal | U12: 68 | V12: 81.963655 | W12: =IF(V12 < 100, "Normal", IF(V12 <= 125, "Prediabetes", "Diabetes")) -> Normal | X12: 0
A13: 0 | B13: =IF(A13=0,"Female","Male") -> Female | C13: 34 | D13: =IF(C13<40,"Young", IF(C13<55,"Middle Age","Senior")) -> Young | E13: 2 | F13: =HLOOKUP(E13, LookUP_Table!$A$6:$D$7, 2, FALSE) -> Secondary | G13: =IFERROR(VLOOKUP(E13, LookUP_Table!$A$1:$B$4, 2, FALSE), "") -> Secondary | H13: 1 | I13: 20 | J13: =IF(I13>0,"Smoker","Non-Smoker") -> Smoker | K13: 0 | L13: 0 | M13: 0 | N13: 0 | O13: 220 | P13: =IF(O13>240,"High","Normal") -> Normal | Q13: 117.5 | R13: 67.5 | S13: 20.79 | T13: =IF(S13<18.5,"Underweight", IF(S13<25,"Normal", IF(S13<30,"Overweight","Obese"))) -> Normal | U13: 63 | V13: 86 | W13: =IF(V13 < 100, "Normal", IF(V13 <= 125, "Prediabetes", "Diabetes")) -> Normal | X13: 0
... A4241: 0 | B4241: =IF(A4241=0,"Female","Male") -> Female | C4241: 70 | D4241: =IF(C4241<40,"Young", IF(C4241<55,"Middle Age","Senior")) -> Senior | E4241: 2 | F4241: =HLOOKUP(E4241, LookUP_Table!$A$6:$D$7, 2, FALSE) -> Secondary | G4241: =IFERROR(VLOOKUP(E4241, LookUP_Table!$A$1:$B$4, 2, FALSE), "") -> Secondary | H4241: 0 | I4241: 0 | J4241: =IF(I4241>0,"Smoker","Non-Smoker") -> Non-Smoker | K4241: 1 | L4241: 0 | M4241: 1 | N4241: 0 | O4241: 231 | P4241: =IF(O4241>240,"High","Normal") -> Normal | Q4241: 136 | R4241: 84 | S4241: 31.78 | T4241: =IF(S4241<18.5,"Underweight", IF(S4241<25,"Normal", IF(S4241<30,"Overweight","Obese"))) -> Obese | U4241: 60 | V4241: 95 | W4241: =IF(V4241 < 100, "Normal", IF(V4241 <= 125, "Prediabetes", "Diabetes")) -> Normal | X4241: 0

Sheet LookUP_Table
A1: 1 | B1: Primary
A2: 2 | B2: Secondary | F2: IFERROR(VLOOKUP(E2, LookUP_Table!$A$1:$B$4, 2, FALSE), "")
A3: 3 | B3: Graduate
A4: 4 | B4: Post Graduate
A6: 1 | B6: 2 | C6: 3 | D6: 4 | F6: HLOOKUP(E2, LookUP_Table!$A$6:$D$7, 2, FALSE)
A7: Primary | B7: Secondary | C7: Graduate | D7: Post Graduate

Sheet Pivot Analysis
A1: Pivot 1: Smokers vs Heart Disease
A2: Row Labels | B2: Heart Disease % by Smoking Status
A3: Non-Smoker | B3: 0.14498834
A4: Smoker | B4: 0.15894988
A5: Grand Total | B5: 0.15188679
A7: Insight:See if smokers have more heart disease.
A16: Pivot 1: BMI_Category vs Heart Disease
A18: Row Labels | B18: Heart Disease % by BMI Category
A19: Normal | B19: 0.12139037
A20: Obese | B20: 0.19480519
A21: Overweight | B21: 0.17136415
A22: Underweight | B22: 0.14035088
A23: Grand Total | B23: 0.15188679
A25: Obese individuals have the highest heart disease risk (19.48%).
A32: Pivot 3: Age Group vs CHD %
A34: Row Labels | B34: Average of TenYearCHD
A35: Middle Age | B35: 0.12336291
A36: Senior | B36: 0.24981017
A37: Young | B37: 0.041366906
A38: Grand Total | B38: 0.15188679
A40: Insight:Heart disease risk increases significantly with age; seniors are most affected.
A47: Pivot 4: Education Level vs CHD
A49: Row Labels | B49: Heart Disease % by Age Group
A50: Graduate | B50: 0.12772134
A51: Post Graduate | B51: 0.14799154
A52: Primary | B52: 0.18575342
A53: Secondary | B53: 0.11731844
A54: Grand Total | B54: 0.15188679
A56: Insight:Lower education groups (Primary/Secondary) show slightly higher CHD cases.
A57: "Primary" and "Secondary" education groups often work in high-stress,
A58: physically demanding, or sedentary jobs with fewer wellness benefits.
A66: Pivot 5: Gender vs CHD
A68: Row Labels | B68: Average of TenYearCHD
A69: Female | B69: 0.12438017
A70: Male | B70: 0.18846154
A71: Grand Total | B71: 0.15188679
A73: Insight:Males have a slightly higher risk of CHD compared to females.
A80: Pivot 6: Glucose Level High vs CHD
A82: Row Labels | B82: Average of TenYearCHD
A83: Normal | B83: 0.15118223
...

Sheet Dashboards

Sheet KPIs
A1: Column1 | B1: Column2
A2: Total Patients | B2: =COUNTA(framingham!X:X,0) -> 4242
A3: Non-CHD Cases | B3: =COUNTIF(framingham!X:X,0) -> 3596
A4: Total CHD Cases | B4: =COUNTIF(framingham!X:X,1) -> 644
A5: CHD % | B5: =B4 / B3 -> 0.17908788
A6: Total Smokers | B6: =COUNTIF(framingham!J:J,"Smoker") -> 2095
A7: Obese % | B7: =COUNTIF(framingham!T:T,"Obese")/COUNTA(framingham!T:T) -> 0.12709267
